Workbook

Sheet IBS-IRG
AI2: الضرائب و الرسوم المحصلة فورا أو عن طريق الاقتطاع من المصدر
E3: المديرية العامة للضرائب | AD3: الشهر | CD3: Série G n°50 (2025)
B4: DIRECTION GENELALE DES IMPOTS | AD4: الفصل | AI4: تصريح يقوم مقام حافظة إشعار بالتسديد
AD5: السنة | BY5: هام:هذا التصريح يجب أن يوضع في قباضة
N6: مديرية | AI6: IMPOTS ET TAXES PERCUS AU COMPTANT OU PAR VOIE | BY6: الضرائب خلال العشرين يوم الأولى من
C7: DIRECTION | AI7: DE RETENUE A LA SOURCE | BY7: الشهر.
AI8: DECLARATION TENANT LIEU DE BORDEREAU- AVIS DEVERSEMENT | BY8: Important : La déclaration doit
K9: مصلحة الضرائب لـ
B10: STRUCTURE DES IMPOTS DE | BY10: être déposée à la recette des
T11: للتذكير إجباريا
BY12: Impôts dans les vingt premiers
F13: قباضة الضرائب لـ
B14: RECETTE DES IMPOTS DE | T14: A RAPPELER | AI14: M : | BQ14: السيد(ة) : | BY14: Jours du mois.
T15: OBLIGATOIREMENT
B16: COMMUNE DE | O16: بلدية
AI17: (social raison - nom et prénom) (الاسم - اللقب - اسم الشركة) | CC17: رمز النشاط
CB19: CODE ACTIVITE
A20: NIN : | AI20: Profession/Activité | BO20: النشاط أو المهنة:
A22: NIF : | AE22: F | AF22: J | AI22: Adresse :
CI23: série G n° 50
A25: Article d'imposition
A28: IBS/ICB : Acompte / solde de liquidation | AQ28: ض.أ.ش/ ض.ت.أ.ش : التسبيقات على الحساب / رصيد التصفية
A29: Code | G29: Acompte/solde de liquidation IBS/ICBS رصيد التصفية/التسبيقات على الحساب | AK29: Détermination de l'acompte provisionnel/solde de liquidation تحديد التسبيق على الحساب/رصيد التصفية | BX29: Montant à pauer (DA) المبلغ المستحق(دج
A30: E1M10 | G30: Acompte provisionnel IBS
G31: solde de liquidation IBS
G32: Acompte provisionnel ICBS
G33: solde de liquidation ICBS
A34: 1 | E34: TOTAL | BX34: =SUM(BX30:CP33) -> 0 | CQ34: =BX34 -> 0
A36: IBS : Retenues à la source | AX36: ض.أ.ش: الإقتطاعات من المصدر
A37: Code | F37: catégories de revenus soumis à la source IBS أصناف المداخيل الخاضعة للاقتطاع من المصدر ض.أ.ش | AY37: base imposable الأساس الضريبي | BP37: المعدل Taux | BX37: Montant à pauer (DA) المبلغ المستحق(دج
A38: E1M30 | F38: IBS/Revenus des entreprises étrangères non installées en Algérie (preestations de services) (1) | BP38: %
A39: E1M40 | F39: IBS/Autres retenues à la source | BP39: %
A40: 2 | E40: (1)joindre le relevé detaillé des retenues à la source par entreprise | AY40: TOTAL | BX40: =SUM(BX38:CP39) -> 0 | CQ40: =BX40 -> 0
A42: IRG (BIC/BNC/RA): Acompte / Solde de liquidation | AW42: ض.د.ا (ا.ص.ت/ا.غ.ت/م.ف): التسبيقات على الحساب / رصيد التصفية
A43: Code | G43: Acompte/solde de liquidation رصيد التصفية/التسبيقات على الحساب | AK43: Détermination de l'acompte provisionnel/solde de liquidation تحديد التسبيق على الحساب/رصيد التصفية | BW43: Montant à pauer (DA) المبلغ المستحق(دج
G44: Acompte provisionnel
G45: solde de liquidation
A46: 3 | E46: TOTAL | BW46: =SUM(BW44:CP45) -> 0 | CQ46: =BW46 -> 0
A48: IRG/ Traitments et salaires et autres retenues à la source | AY48: ض.د.ا / الأجور و الإقتطاعات الأخرى من المصدر
A49: Code | G49: Catégories de revenus soumis à une retenue à la source IRG أصناف المداخيل الخاضعة للاقتطاع من المصدر | BP49: المعدل Taux | BX49: Montant à pauer (DA) المبلغ المستحق(دج
...

Sheet TLS
D1: Taxe Locale de Solidarité (T.L.S) | BB1: الـــرســــــم المحلي للتضامن
D2: I . Régime du Paiement mensuel :
D3: Code | J3: Opérations imposables العمليات الخاضعة للضريبة | AN3: رقم الأعمال Chiffre d'affaires | BK3: أساس فرض الضريبة Base imposable | CH3: Taux | CL3: Montant à payer (en DA)
CH4: المعدل | CL4: المبلغ المستحق (دج)
J5: 1) Activité de transport par canalisation des | CH5: 0.03 | CL5: =BK5*CH5 -> 0
J6: hydrocarbures
J7: 2) Activité miniéres : | CH7: 0.015 | CL7: =+BK7*CH7 -> 0
J8: Opérations bénéficiant de la réféction de 30%
J9: Opérations sansa réféction
J10: Opérations exonérées ou non imposables
J11: - AAPI
J12: - ANDI
J13: - ANADE
J14: - ANGEM
J15: - CNAC
J16: - Opérations intra groupe
J17: - Opérations inter-unités
J18: - Autres …(à préciser)
D19: Opération pour le régime des acomptes provisionnels (1)
D20: II. Régime des acomptes provisionel :
D21: Code | J21: Opérations imposables العمليات الخاضعة للضريبة | AM21: رقم الأعمال Chiffre d'affaires | BK21: أساس حساب التسبيقات(2) Base de calcul des acomptes | CH21: Taux | CL21: Montant à payer (en DA) المبلغ المستحق (دج
CH22: المعدل
J23: 1) Activité de transpor par canalisation des | CH23: 0.03 | CL23: =BK23*CH23 -> 0
J24: hydrocarbures
J25: période de référence (a préciser) :
J26: Ou Date de notification (à préciser) :
J27: ● Montant de l'acompte
J28: ● Montant du solde de liquidation
J29: 2) activités minières : | CH29: 0.015 | CL29: =+BK29*CH29 -> 0
J30: période de référence (a préciser) :
J31: Ou date de notification (à préciser) :
J32: ● Montant de l'acompte
J33: ● Montant du solde de liquidation
D34: 5 | AE34: TOTAL | AM34: =SUM(AM23:BJ33) -> 0 | BK34: =SUM(BK23:CG33) -> 0 | CL34: =+CL33+CL32+CL31+CL30+CL29+CL28+CL27+CL26+CL25+CL23+CL18+CL17+CL16+CL15+CL14+CL13+CL12+CL11+CL10+CL9+CL8+CL7+CL5 -> 0
D36: (1) Cocher la case en cas d'option.
D37: (2) La base de calcul des acomptes provisionnels mensuel en matière de la TLS est déterminée suivant les dispositions de l'article 364 octies du CIDTA

Sheet TIMBRE
E3: Droit de timbre sur état (1) | AT3: حــــــق الطـــــــــــابع
E4: Code | I4: Opérations imposables | AA4: العمليات الخاضعة للضريبة | AT4: Chiffre d'affaires imposable رقم الاعمال الخاضع | BL4: Taux | BP4: Montant a payer (en DA)
AT5: للضريبة | BL5: المعدل
E6: E2 E00 | BL6: 0.01 | BP6: =+AT6*BL6 -> 0
BL7: 0.015 | BP7: =+AT7*BL7 -> 0
BL8: 0.02 | BP8: =+AT8*BL8 -> 0
E9: 6 | G9: (1) Ce cadre est utilisé notamment par les contribuables qui auront demandé à s'acquitter du droit de | AT9: TOTAL | BP9: =SUM(BP6:CJ8) -> 0
G10: timbre sur état
E12: Impôts et taxes non repris ci-dessus (Autres : à préciser) | AV12: الضـــرائب والرســــوم الغيـــــر واردة أعـــــــلاه (خلافه : مع التوضيح)
E13: Code | K13: impôts et taxes | AC13: الضرائب و الرسوم | AV13: Base d'imposition الأساس الضريبي | BO13: taux | BS13: المبلغ المستحق(دج)( Montant à payer(da
BO14: المعدل
BO15: %
BO16: %
BO17: %
E21: 7 | I21: TOTAL | BS21: =SUM(BS15:CJ20) -> 0
E23: RECAPITULATION (EN DA) | AB23: تـــلــخــــيـــص بــ (دج) | AN23: Cadre réservé au contribuable | BB23: cadre réservé à la recette des impôts | BW23: cadre réservé au service d'assiette
AN24: إطار خاص بالمكلف بالضريبة | BB24: إطار خاص بقباضة الضرائب | BW24: إطار خاص بمصلحة الوعاء
AN25: يشهد بصحة وصدق محتوى هذا التصريح | BB25: Reçu - ce jour la présente déclaration enregistrée | BW25: déclaration Eenregistrée le: ……..
AN26: و تطابقه مع الوثائق المحاسبية | BB26: sous le Numrro: ………………….…….......................... | BW26: ……………………………………………..
E27: 1-AP/SL-IBS/CBS | R27: C/201001/102 | AB27: ='IBS-IRG'!CQ34 -> 0 | AN27: Certifie sincère et véritable le | BB27: Payée-par Chéque bancaire N°……………..……………
E28: 2-IBS/Retenues à la Source | R28: C/201001/L3 | AB28: ='IBS-IRG'!CQ40 -> 0 | AN28: contenu de la présente déclaration | BB28: du ……....................................................................... | BW28: Observations éventuelles
E29: 3-AP/SL-IRG(BIC/BNC) et | R29: C/201001/101 | AB29: ='IBS-IRG'!CQ46 -> 0 | AN29: et conforme aux documents | BB29: tiré sur l'Agence: ……………………………………………… | BW29: …………………………………………….
E30: AP/RA | AN30: comptables | BB30: -par chéque postal N° :…………….…………………... | BW30: …………………………………………….
E31: 4-IRG/Retenues à la source | R31: C/201001/A/B/ | AB31: ='IBS-IRG'!CQ56 -> 0 | AN31: A | AU31: le | BB31: -en numéraire :……………………………………………….... | BW31: …………………………………………….
E32: 5-TLS | R32: C/500028L/7 | AB32: =TLS!CL34 -> 0 | AN32: Cachet Signature | BB32: Prise en recette par quittance N° …………….……. | BW32: …………………………………………….
E33: 6-Droits de timbre | R33: C/201001/102 | AB33: =BP9 -> 0 | BB33: de ce jour | BW33: …………………………………………….
E34: 7-Autres | R34: C/………….. | AB34: =BS21 -> 0 | BB34: A | BC34: …………………………… | BL34: le | BN34: ………………………….. | BW34: …………………………………………….
E35: 8-tva | R35: C/500020/A | AB35: =TVA!CD42 -> 0 | BB35: Le receveur des impôts | BW35: …………………………………………….
BB36: Cachet signature | BW36: …………………………………………….
BW37: …………………………………………….
BW38: …………………………………………….
E39: MONTANT TOTAL APAYER | AB39: =SUM(AB27:AM36) -> 0 | BW39: …………………………………………….

Sheet TVA
E1: Les chiffres d'affaires et les recettes | AF1: الرسم على القيمة المضافة | BU1: تسجيل أرقام الاعمال و الايرادات المهنية بالدينار
E3: porfessionnelles sont inscrits en dinars le dernier | AF3: TAXE SUR LA VALEUR AJOUTEE | BU3: و العدد الأخير يراجع الى الصفر
E5: chiffre étant ramené au zéro ( Exemple 325.626 | AF5: A/ Chiffres d'affaires imposables أ ـ رقم الأعمال الخاضع الضريبة | BU5: ( مثال 325,620 = 325,626دج )
E6: DA = 325.620 DA)
E7: الرمز | I7: Opérations assujetties à la TVA العمليات الخاضعة الرسم على القيمة المضافة | AQ7: مجموع رقم الاعمال | BD7: رقم الاعمال المعفى | BQ7: رقم الاعمال الخاضع للضريبة | CE7: Taux | CH7: المبلغ المدفوع بـ (دج)
BQ8: Chiffre d'affaires
E9: Code | AQ9: Chiffre d'affaires Total | BD9: Chiffre d'affaires Exonéré | BQ9: Imposable | CE9: المعدل | CH9: Montant des droits (en DA)
E10: E3B11 | I10: Biens produits et denrées visées par l'article 23 du C.TCA | CE10: 0.09 | CH10: =BQ10*0.09 -> 0
E11: E3B12 | I11: Prestations de services visées par l'article 23 du C.TCA | CE11: " | CH11: =BQ11*0.09 -> 0
E12: E3B13 | I12: Opérations immobilières visées par l'article 23 du C.TCA | CE12: " | CH12: =BQ12*0.09 -> 0
E13: E3B14 | I13: Actes Médicaux | CE13: " | CH13: =BQ13*0.09 -> 0
E14: E3B15 | I14: Commissionnaire et cortiers | CE14: " | CH14: =BQ14*0.09 -> 0
E15: E3B16 | I15: Fournitured'énergie | CE15: " | CH15: =BQ15*0.09 -> 0
E16: E3B21 | I16: Production : biens, produits, denrées visées par l'article 23 du C.TCA | CE16: 0.19 | CH16: =BQ16*0.19 -> 0
E17: E3B22 | I17: Revente en l'état : biens, produits, denrées visées par l'article 23 du C.TCA | CE17: " | CH17: =BQ17*0.19 -> 0
E18: E3B23 | I18: Travaux immobiliers autres que ceux soumis au taux de 9% | CE18: " | CH18: =BQ18*0.19 -> 0
E19: E3B24 | I19: Professions Libérales | CE19: " | CH19: =BQ19*0.19 -> 0
E20: E3B25 | I20: Opérations de banques et assurances | CE20: " | CH20: =BQ20*0.19 -> 0
E21: E3B26 | I21: Prestations de téléphone et télex | CE21: " | CH21: =BQ21*0.19 -> 0
E22: E3B28 | I22: Autres prestations de services | CE22: " | CH22: =BQ22*0.19 -> 0
E23: E3B31 | I23: Débits de boissons | CE23: " | CH23: =BQ23*0.19 -> 0
E24: E3B32 | I24: Production biens et denrées visées par l'article 23 du C.TCA | CE24: " | CH24: =BQ24*0.19 -> 0
E25: E3B33 | I25: Reventes en l'état biens produits et denrées visées par l'article 23 du C.TCA | CE25: " | CH25: =BQ25*0.19 -> 0
E26: E3B34 | I26: Tabacs et allumettes | CE26: " | CH26: =BQ26*0.19 -> 0
E27: E3B35 | I27: Spectacles, jeux et divertissement autres que ceux de l'art 21 du C TCA | CE27: " | CH27: =BQ27*0.19 -> 0
E28: E3B36 | I28: Autres prestations de services visées par l'article 23 du C.TCA | CE28: " | CH28: =BQ28*0.19 -> 0
E29: E3B37 | I29: Consommations sur place | CE29: " | CH29: =BQ29*0.19 -> 0
I30: Autres | CE30: " | CH30: =BQ30*0.19 -> 0
I31: المـجـمــوع العـــام لـــرقـــم الاعــمــــــال | CH31: =SUM(CH10:CT30) -> 0
I32: TOTAL GENERAL DES CHIFFRES D'AFFAIRES
I33: B/ Déductions à opérer | AO33: ب - الحسومات المجراة: | BB33: C/ TVA à Payer | CC33: ت - ر. ق.م الواجب دفعه
I34: Nature des déductions | AO34: Montant
E35: E3B91 | I35: Précompte antérieur (mois précédent) | BD35: C | BI35: - Total des droits dus | CD35: =CH31 -> 0
E36: E3B92 | I36: TVA / achats de matières et services (art.29 C TCA) | BD36: E3B97 | BI36: Régularisation du prorata (art 40 c TCA)
E37: E3B93 | I37: TVA / achats biens amortissables (art.38 C TCA) | BI37: (+) (déduction excédentaire)
E38: E3B94 | I38: Régularisation prorata déduction (art.40 C TCA) | BD38: E3B98 | BI38: - Reversement (art.38CTCA)(+)
E39: E3B95 | I39: TCA).TVA à récupérer surfactures annulées ou impayées (art. 18 C
E40: E3B96 | I40: TCA) … | BI40: TOTAL A RAPPELER (C) مجموع المستحقات | CD40: =CD38+CD36+CD35 -> 0
I41: Autres déductions (Notification de précomptes, etc.) | BD41: B | BI41: - Total des déductions (B) (-) | CD41: =AO44 -> 0
I42: NB: Joindre un etat détallé des fournisseurs conformément à l'article | BD42: E3B00 | BI42: TVA a Payer au titre du mois (C-B) | CD42: =IF(CD40-CD41>0,CD40-CD41,0) -> 0
...

Sheet compta-fisco
B10: للإستفادة اكثر في مجال المحاسبة و الجباية
A13: compta-fisco | B13: قناتي على فيسبوك | C13: https://web.facebook.com/profile.php?id=61574198014292
A14: comptable qualifie | B14: صفحتي على فيسبوك | C14: https://web.facebook.com/comptable.qualifie
A15: compta fisco | B15: قناتي على اليوتوب | C15: https://www.youtube.com/@compta-fisco
